Workbook
Name ps: Sheet2!$L$3:$O$27

Sheet Sheet1
A1: Log Automate Studio 24.1 SAP System: Client: SAP User - Q01:400:MMASTER Script Name - ZMPS1 Create_S4H.Txr Mode - Standard (Non Batch without controls) Start Row - 2 End Row - 4 Number of Errors - 0 Records Uploaded - 3 Date and Time - 10/07/2026 14:56:21 Execution Time - 0:00:38 Run Reason - | B1: Material Number RMMG1-MATNR | C1: Material Description (Short Text) MAKT-MAKTX | D1: Base Unit of Measure MARA-MEINS | E1: Division MARA-SPART | F1: Material Group MARA-MATKL | G1: Product hierarchy MARA-PRDHA | H1: Industry Standard Description (such as ANSI or ISO) MARA-NORMT | I1: Manufacturer Part Number MARA-MFRPN | J1: Number of a Manufacturer MARA-MFRNR | K1: Segment Data MARA-FERTH
B2: ='BIE Creation Sheet'!L2 | C2: ='BIE Creation Sheet'!M2 | D2: ='BIE Creation Sheet'!C2 | E2: ='BIE Creation Sheet'!P2 | F2: ='BIE Creation Sheet'!Q2 | G2: ='BIE Creation Sheet'!R2 | H2: =B2 | I2: =B2 | J2: ='BIE Creation Sheet'!F2 | K2: ='BIE Creation Sheet'!B2
B3: ='BIE Creation Sheet'!L3 | C3: ='BIE Creation Sheet'!M3 | D3: ='BIE Creation Sheet'!C3 | E3: ='BIE Creation Sheet'!P3 | F3: ='BIE Creation Sheet'!Q3 | G3: ='BIE Creation Sheet'!R3 | H3: =B3 | I3: =B3 | J3: ='BIE Creation Sheet'!F3 | K3: ='BIE Creation Sheet'!B3
B4: ='BIE Creation Sheet'!L4 | C4: ='BIE Creation Sheet'!M4 | D4: ='BIE Creation Sheet'!C4 | E4: ='BIE Creation Sheet'!P4 | F4: ='BIE Creation Sheet'!Q4 | G4: ='BIE Creation Sheet'!R4 | H4: =B4 | I4: =B4 | J4: ='BIE Creation Sheet'!F4 | K4: ='BIE Creation Sheet'!B4
B5: ='BIE Creation Sheet'!L5 | C5: ='BIE Creation Sheet'!M5 | D5: ='BIE Creation Sheet'!C5 | E5: ='BIE Creation Sheet'!P5 | F5: ='BIE Creation Sheet'!Q5 | G5: ='BIE Creation Sheet'!R5 | H5: =B5 | I5: =B5 | J5: ='BIE Creation Sheet'!F5 | K5: ='BIE Creation Sheet'!B5
B6: ='BIE Creation Sheet'!L6 | C6: ='BIE Creation Sheet'!M6 | D6: ='BIE Creation Sheet'!C6 | E6: ='BIE Creation Sheet'!P6 | F6: ='BIE Creation Sheet'!Q6 | G6: ='BIE Creation Sheet'!R6 | H6: =B6 | I6: =B6 | J6: ='BIE Creation Sheet'!F6 | K6: ='BIE Creation Sheet'!B6
B7: ='BIE Creation Sheet'!L7 | C7: ='BIE Creation Sheet'!M7 | D7: ='BIE Creation Sheet'!C7 | E7: ='BIE Creation Sheet'!P7 | F7: ='BIE Creation Sheet'!Q7 | G7: ='BIE Creation Sheet'!R7 | H7: =B7 | I7: =B7 | J7: ='BIE Creation Sheet'!F7 | K7: ='BIE Creation Sheet'!B7
B8: ='BIE Creation Sheet'!L8 | C8: ='BIE Creation Sheet'!M8 | D8: ='BIE Creation Sheet'!C8 | E8: ='BIE Creation Sheet'!P8 | F8: ='BIE Creation Sheet'!Q8 | G8: ='BIE Creation Sheet'!R8 | H8: =B8 | I8: =B8 | J8: ='BIE Creation Sheet'!F8 | K8: ='BIE Creation Sheet'!B8
B9: ='BIE Creation Sheet'!L9 | C9: ='BIE Creation Sheet'!M9 | D9: ='BIE Creation Sheet'!C9 | E9: ='BIE Creation Sheet'!P9 | F9: ='BIE Creation Sheet'!Q9 | G9: ='BIE Creation Sheet'!R9 | H9: =B9 | I9: =B9 | J9: ='BIE Creation Sheet'!F9 | K9: ='BIE Creation Sheet'!B9
B10: ='BIE Creation Sheet'!L10 | C10: ='BIE Creation Sheet'!M10 | D10: ='BIE Creation Sheet'!C10 | E10: ='BIE Creation Sheet'!P10 | F10: ='BIE Creation Sheet'!Q10 | G10: ='BIE Creation Sheet'!R10 | H10: =B10 | I10: =B10 | J10: ='BIE Creation Sheet'!F10 | K10: ='BIE Creation Sheet'!B10
B11: ='BIE Creation Sheet'!L11 | C11: ='BIE Creation Sheet'!M11 | D11: ='BIE Creation Sheet'!C11 | E11: ='BIE Creation Sheet'!P11 | F11: ='BIE Creation Sheet'!Q11 | G11: ='BIE Creation Sheet'!R11 | H11: =B11 | I11: =B11 | J11: ='BIE Creation Sheet'!F11 | K11: ='BIE Creation Sheet'!B11
B12: ='BIE Creation Sheet'!L12 | C12: ='BIE Creation Sheet'!M12 | D12: ='BIE Creation Sheet'!C12 | E12: ='BIE Creation Sheet'!P12 | F12: ='BIE Creation Sheet'!Q12 | G12: ='BIE Creation Sheet'!R12 | H12: =B12 | I12: =B12 | J12: ='BIE Creation Sheet'!F12 | K12: ='BIE Creation Sheet'!B12
B13: ='BIE Creation Sheet'!L13 | C13: ='BIE Creation Sheet'!M13 | D13: ='BIE Creation Sheet'!C13 | E13: ='BIE Creation Sheet'!P13 | F13: ='BIE Creation Sheet'!Q13 | G13: ='BIE Creation Sheet'!R13 | H13: =B13 | I13: =B13 | J13: ='BIE Creation Sheet'!F13 | K13: ='BIE Creation Sheet'!B13
... B50: ='BIE Creation Sheet'!L50 | C50: ='BIE Creation Sheet'!M50 | D50: ='BIE Creation Sheet'!C50 | E50: ='BIE Creation Sheet'!P50 | F50: ='BIE Creation Sheet'!Q50 | G50: ='BIE Creation Sheet'!R50 | H50: =B50 | I50: =B50 | J50: ='BIE Creation Sheet'!F50 | K50: ='BIE Creation Sheet'!B50

Sheet Sheet2
A1: Log Automate Studio 24.1 SAP System: Client: SAP User - Q01:400:MMASTER Script Name - ZMPS2_S4H.Txr Mode - Standard (Non Batch without controls) Start Row - 57 End Row - 76 Number of Errors - 0 Records Uploaded - 20 Date and Time - 10/07/2026 15:03:50 Execution Time - 0:00:12 Run Reason - | B1: Material Number RMMG1-MATNR | C1: Plant RMMG1-WERKS | D1: Sales Organization RMMG1-VKORG | E1: Distribution Channel RMMG1-VTWEG | F1: Delivering Plant (Own or External) MVKE-DWERK | G1: Material Pricing Group MVKE-KONDM | H1: Product hierarchy MVKE-PRODH | I1: Country of origin of the material MARC-HERKL | J1: Standard price MBEW-STPRS | Q1: No of materials | R1: Entries per material | S1: Drag it to row
B2: {=INDEX('BIE Creation Sheet'!L:L,INT((ROW()-2)/25)+2)} | C2: =CHOOSE(MOD(ROW()-2,26)+1, "D20","D21","D28","D29","D81","E21","E31","E51","E61","E62","E73","E83","F01","F11","F12","G12","H41","E01","I21","I41","E91","E92","E23","E81","D22","D20") | D2: =CHOOSE(MOD(ROW()-2,25)+1, "BNF","BND","BNN","BNS","BIA", "BUK","BIR","BBE","BNL","BNL", "BFR","BIG","BSW","BIT","BIT", "BES","BPT","BIE","BPL1","BCZ1", "BAT","BAT","BUK","BIG","BND") | E2: ="01" | F2: =CHOOSE(MOD(ROW()-2,25)+1, "D20","D21","D28","D29","D81", "E21","E31","E51","E61","E62", "E73","E83","F01","F11","F12", "G12","H41","E01","E92","E92", "E92","E92","E21","E83","D22") | G2: {=INDEX('BIE Creation Sheet'!X:X,INT((ROW()-2)/25)+2)} | H2: {=INDEX('BIE Creation Sheet'!R:R,INT((ROW()-2)/25)+2)} | I2: =CHOOSE(MOD(ROW()-2,25)+1, "FI","DK","SV","NO","DE", "GB","IR","BE","NL","NL", "FR","DE","CH","IT","IT", "ES","PT","GB","PL","CZ", "AT","AT","GB","DE","DK") | J2: =0.01 | L2: Not at E01 BIE | O2: del plant
B3: {=INDEX('BIE Creation Sheet'!L:L,INT((ROW()-2)/25)+2)} | C3: =CHOOSE(MOD(ROW()-2,26)+1, "D20","D21","D28","D29","D81","E21","E31","E51","E61","E62","E73","E83","F01","F11","F12","G12","H41","E01","I21","I41","E91","E92","E23","E81","D22","D20") | D3: =CHOOSE(MOD(ROW()-2,25)+1, "BNF","BND","BNN","BNS","BIA", "BUK","BIR","BBE","BNL","BNL", "BFR","BIG","BSW","BIT","BIT", "BES","BPT","BIE","BPL1","BCZ1", "BAT","BAT","BUK","BIG","BND") | E3: ="01" | F3: =CHOOSE(MOD(ROW()-2,25)+1, "D20","D21","D28","D29","D81", "E21","E31","E51","E61","E62", "E73","E83","F01","F11","F12", "G12","H41","E01","E92","E92", "E92","E92","E21","E83","D22") | G3: {=INDEX('BIE Creation Sheet'!X:X,INT((ROW()-2)/25)+2)} | H3: {=INDEX('BIE Creation Sheet'!R:R,INT((ROW()-2)/25)+2)} | I3: =CHOOSE(MOD(ROW()-2,25)+1, "FI","DK","SV","NO","DE", "GB","IR","BE","NL","NL", "FR","DE","CH","IT","IT", "ES","PT","GB","PL","CZ", "AT","AT","GB","DE","DK") | J3: =0.01 | L3: D20 | M3: BNF | N3: FI | O3: D20 | Q3: 2 | R3: 25 | S3: =Q3*R3+1
B4: {=INDEX('BIE Creation Sheet'!L:L,INT((ROW()-2)/25)+2)} | C4: =CHOOSE(MOD(ROW()-2,26)+1, "D20","D21","D28","D29","D81","E21","E31","E51","E61","E62","E73","E83","F01","F11","F12","G12","H41","E01","I21","I41","E91","E92","E23","E81","D22","D20") | D4: =CHOOSE(MOD(ROW()-2,25)+1, "BNF","BND","BNN","BNS","BIA", "BUK","BIR","BBE","BNL","BNL", "BFR","BIG","BSW","BIT","BIT", "BES","BPT","BIE","BPL1","BCZ1", "BAT","BAT","BUK","BIG","BND") | E4: ="01" | F4: =CHOOSE(MOD(ROW()-2,25)+1, "D20","D21","D28","D29","D81", "E21","E31","E51","E61","E62", "E73","E83","F01","F11","F12", "G12","H41","E01","E92","E92", "E92","E92","E21","E83","D22") | G4: {=INDEX('BIE Creation Sheet'!X:X,INT((ROW()-2)/25)+2)} | H4: {=INDEX('BIE Creation Sheet'!R:R,INT((ROW()-2)/25)+2)} | I4: =CHOOSE(MOD(ROW()-2,25)+1, "FI","DK","SV","NO","DE", "GB","IR","BE","NL","NL", "FR","DE","CH","IT","IT", "ES","PT","GB","PL","CZ", "AT","AT","GB","DE","DK") | J4: =0.01 | L4: D21 | M4: BND | N4: DK | O4: D21
B5: {=INDEX('BIE Creation Sheet'!L:L,INT((ROW()-2)/25)+2)} | C5: =CHOOSE(MOD(ROW()-2,26)+1, "D20","D21","D28","D29","D81","E21","E31","E51","E61","E62","E73","E83","F01","F11","F12","G12","H41","E01","I21","I41","E91","E92","E23","E81","D22","D20") | D5: =CHOOSE(MOD(ROW()-2,25)+1, "BNF","BND","BNN","BNS","BIA", "BUK","BIR","BBE","BNL","BNL", "BFR","BIG","BSW","BIT","BIT", "BES","BPT","BIE","BPL1","BCZ1", "BAT","BAT","BUK","BIG","BND") | E5: ="01" | F5: =CHOOSE(MOD(ROW()-2,25)+1, "D20","D21","D28","D29","D81", "E21","E31","E51","E61","E62", "E73","E83","F01","F11","F12", "G12","H41","E01","E92","E92", "E92","E92","E21","E83","D22") | G5: {=INDEX('BIE Creation Sheet'!X:X,INT((ROW()-2)/25)+2)} | H5: {=INDEX('BIE Creation Sheet'!R:R,INT((ROW()-2)/25)+2)} | I5: =CHOOSE(MOD(ROW()-2,25)+1, "FI","DK","SV","NO","DE", "GB","IR","BE","NL","NL", "FR","DE","CH","IT","IT", "ES","PT","GB","PL","CZ", "AT","AT","GB","DE","DK") | J5: =0.01 | L5: D28 | M5: BNN | N5: SV | O5: D28
B6: {=INDEX('BIE Creation Sheet'!L:L,INT((ROW()-2)/25)+2)} | C6: =CHOOSE(MOD(ROW()-2,26)+1, "D20","D21","D28","D29","D81","E21","E31","E51","E61","E62","E73","E83","F01","F11","F12","G12","H41","E01","I21","I41","E91","E92","E23","E81","D22","D20") | D6: =CHOOSE(MOD(ROW()-2,25)+1, "BNF","BND","BNN","BNS","BIA", "BUK","BIR","BBE","BNL","BNL", "BFR","BIG","BSW","BIT","BIT", "BES","BPT","BIE","BPL1","BCZ1", "BAT","BAT","BUK","BIG","BND") | E6: ="01" | F6: =CHOOSE(MOD(ROW()-2,25)+1, "D20","D21","D28","D29","D81", "E21","E31","E51","E61","E62", "E73","E83","F01","F11","F12", "G12","H41","E01","E92","E92", "E92","E92","E21","E83","D22") | G6: {=INDEX('BIE Creation Sheet'!X:X,INT((ROW()-2)/25)+2)} | H6: {=INDEX('BIE Creation Sheet'!R:R,INT((ROW()-2)/25)+2)} | I6: =CHOOSE(MOD(ROW()-2,25)+1, "FI","DK","SV","NO","DE", "GB","IR","BE","NL","NL", "FR","DE","CH","IT","IT", "ES","PT","GB","PL","CZ", "AT","AT","GB","DE","DK") | J6: =0.01 | L6: D29 | M6: BNS | N6: NO | O6: D29
B7: {=INDEX('BIE Creation Sheet'!L:L,INT((ROW()-2)/25)+2)} | C7: =CHOOSE(MOD(ROW()-2,26)+1, "D20","D21","D28","D29","D81","E21","E31","E51","E61","E62","E73","E83","F01","F11","F12","G12","H41","E01","I21","I41","E91","E92","E23","E81","D22","D20") | D7: =CHOOSE(MOD(ROW()-2,25)+1, "BNF","BND","BNN","BNS","BIA", "BUK","BIR","BBE","BNL","BNL", "BFR","BIG","BSW","BIT","BIT", "BES","BPT","BIE","BPL1","BCZ1", "BAT","BAT","BUK","BIG","BND") | E7: ="01" | F7: =CHOOSE(MOD(ROW()-2,25)+1, "D20","D21","D28","D29","D81", "E21","E31","E51","E61","E62", "E73","E83","F01","F11","F12", "G12","H41","E01","E92","E92", "E92","E92","E21","E83","D22") | G7: {=INDEX('BIE Creation Sheet'!X:X,INT((ROW()-2)/25)+2)} | H7: {=INDEX('BIE Creation Sheet'!R:R,INT((ROW()-2)/25)+2)} | I7: =CHOOSE(MOD(ROW()-2,25)+1, "FI","DK","SV","NO","DE", "GB","IR","BE","NL","NL", "FR","DE","CH","IT","IT", "ES","PT","GB","PL","CZ", "AT","AT","GB","DE","DK") | J7: =0.01 | L7: D81 | M7: BIA | N7: DE | O7: D81
B8: {=INDEX('BIE Creation Sheet'!L:L,INT((ROW()-2)/25)+2)} | C8: =CHOOSE(MOD(ROW()-2,26)+1, "D20","D21","D28","D29","D81","E21","E31","E51","E61","E62","E73","E83","F01","F11","F12","G12","H41","E01","I21","I41","E91","E92","E23","E81","D22","D20") | D8: =CHOOSE(MOD(ROW()-2,25)+1, "BNF","BND","BNN","BNS","BIA", "BUK","BIR","BBE","BNL","BNL", "BFR","BIG","BSW","BIT","BIT", "BES","BPT","BIE","BPL1","BCZ1", "BAT","BAT","BUK","BIG","BND") | E8: ="01" | F8: =CHOOSE(MOD(ROW()-2,25)+1, "D20","D21","D28","D29","D81", "E21","E31","E51","E61","E62", "E73","E83","F01","F11","F12", "G12","H41","E01","E92","E92", "E92","E92","E21","E83","D22") | G8: {=INDEX('BIE Creation Sheet'!X:X,INT((ROW()-2)/25)+2)} | H8: {=INDEX('BIE Creation Sheet'!R:R,INT((ROW()-2)/25)+2)} | I8: =CHOOSE(MOD(ROW()-2,25)+1, "FI","DK","SV","NO","DE", "GB","IR","BE","NL","NL", "FR","DE","CH","IT","IT", "ES","PT","GB","PL","CZ", "AT","AT","GB","DE","DK") | J8: =0.01 | L8: E21 | M8: BUK | N8: GB | O8: E21
B9: {=INDEX('BIE Creation Sheet'!L:L,INT((ROW()-2)/25)+2)} | C9: =CHOOSE(MOD(ROW()-2,26)+1, "D20","D21","D28","D29","D81","E21","E31","E51","E61","E62","E73","E83","F01","F11","F12","G12","H41","E01","I21","I41","E91","E92","E23","E81","D22","D20") | D9: =CHOOSE(MOD(ROW()-2,25)+1, "BNF","BND","BNN","BNS","BIA", "BUK","BIR","BBE","BNL","BNL", "BFR","BIG","BSW","BIT","BIT", "BES","BPT","BIE","BPL1","BCZ1", "BAT","BAT","BUK","BIG","BND") | E9: ="01" | F9: =CHOOSE(MOD(ROW()-2,25)+1, "D20","D21","D28","D29","D81", "E21","E31","E51","E61","E62", "E73","E83","F01","F11","F12", "G12","H41","E01","E92","E92", "E92","E92","E21","E83","D22") | G9: {=INDEX('BIE Creation Sheet'!X:X,INT((ROW()-2)/25)+2)} | H9: {=INDEX('BIE Creation Sheet'!R:R,INT((ROW()-2)/25)+2)} | I9: =CHOOSE(MOD(ROW()-2,25)+1, "FI","DK","SV","NO","DE", "GB","IR","BE","NL","NL", "FR","DE","CH","IT","IT", "ES","PT","GB","PL","CZ", "AT","AT","GB","DE","DK") | J9: =0.01 | L9: E31 | M9: BIR | N9: IR | O9: E31
B10: {=INDEX('BIE Creation Sheet'!L:L,INT((ROW()-2)/25)+2)} | C10: =CHOOSE(MOD(ROW()-2,26)+1, "D20","D21","D28","D29","D81","E21","E31","E51","E61","E62","E73","E83","F01","F11","F12","G12","H41","E01","I21","I41","E91","E92","E23","E81","D22","D20") | D10: =CHOOSE(MOD(ROW()-2,25)+1, "BNF","BND","BNN","BNS","BIA", "BUK","BIR","BBE","BNL","BNL", "BFR","BIG","BSW","BIT","BIT", "BES","BPT","BIE","BPL1","BCZ1", "BAT","BAT","BUK","BIG","BND") | E10: ="01" | F10: =CHOOSE(MOD(ROW()-2,25)+1, "D20","D21","D28","D29","D81", "E21","E31","E51","E61","E62", "E73","E83","F01","F11","F12", "G12","H41","E01","E92","E92", "E92","E92","E21","E83","D22") | G10: {=INDEX('BIE Creation Sheet'!X:X,INT((ROW()-2)/25)+2)} | H10: {=INDEX('BIE Creation Sheet'!R:R,INT((ROW()-2)/25)+2)} | I10: =CHOOSE(MOD(ROW()-2,25)+1, "FI","DK","SV","NO","DE", "GB","IR","BE","NL","NL", "FR","DE","CH","IT","IT", "ES","PT","GB","PL","CZ", "AT","AT","GB","DE","DK") | J10: =0.01 | L10: E51 | M10: BBE | N10: BE | O10: E51
B11: {=INDEX('BIE Creation Sheet'!L:L,INT((ROW()-2)/25)+2)} | C11: =CHOOSE(MOD(ROW()-2,26)+1, "D20","D21","D28","D29","D81","E21","E31","E51","E61","E62","E73","E83","F01","F11","F12","G12","H41","E01","I21","I41","E91","E92","E23","E81","D22","D20") | D11: =CHOOSE(MOD(ROW()-2,25)+1, "BNF","BND","BNN","BNS","BIA", "BUK","BIR","BBE","BNL","BNL", "BFR","BIG","BSW","BIT","BIT", "BES","BPT","BIE","BPL1","BCZ1", "BAT","BAT","BUK","BIG","BND") | E11: ="01" | F11: =CHOOSE(MOD(ROW()-2,25)+1, "D20","D21","D28","D29","D81", "E21","E31","E51","E61","E62", "E73","E83","F01","F11","F12", "G12","H41","E01","E92","E92", "E92","E92","E21","E83","D22") | G11: {=INDEX('BIE Creation Sheet'!X:X,INT((ROW()-2)/25)+2)} | H11: {=INDEX('BIE Creation Sheet'!R:R,INT((ROW()-2)/25)+2)} | I11: =CHOOSE(MOD(ROW()-2,25)+1, "FI","DK","SV","NO","DE", "GB","IR","BE","NL","NL", "FR","DE","CH","IT","IT", "ES","PT","GB","PL","CZ", "AT","AT","GB","DE","DK") | J11: =0.01 | L11: E61 | M11: BNL | N11: NL | O11: E61
B12: {=INDEX('BIE Creation Sheet'!L:L,INT((ROW()-2)/25)+2)} | C12: =CHOOSE(MOD(ROW()-2,26)+1, "D20","D21","D28","D29","D81","E21","E31","E51","E61","E62","E73","E83","F01","F11","F12","G12","H41","E01","I21","I41","E91","E92","E23","E81","D22","D20") | D12: =CHOOSE(MOD(ROW()-2,25)+1, "BNF","BND","BNN","BNS","BIA", "BUK","BIR","BBE","BNL","BNL", "BFR","BIG","BSW","BIT","BIT", "BES","BPT","BIE","BPL1","BCZ1", "BAT","BAT","BUK","BIG","BND") | E12: ="01" | F12: =CHOOSE(MOD(ROW()-2,25)+1, "D20","D21","D28","D29","D81", "E21","E31","E51","E61","E62", "E73","E83","F01","F11","F12", "G12","H41","E01","E92","E92", "E92","E92","E21","E83","D22") | G12: {=INDEX('BIE Creation Sheet'!X:X,INT((ROW()-2)/25)+2)} | H12: {=INDEX('BIE Creation Sheet'!R:R,INT((ROW()-2)/25)+2)} | I12: =CHOOSE(MOD(ROW()-2,25)+1, "FI","DK","SV","NO","DE", "GB","IR","BE","NL","NL", "FR","DE","CH","IT","IT", "ES","PT","GB","PL","CZ", "AT","AT","GB","DE","DK") | J12: =0.01 | L12: E62 | M12: BNL | N12: NL | O12: E62
B13: {=INDEX('BIE Creation Sheet'!L:L,INT((ROW()-2)/25)+2)} | C13: =CHOOSE(MOD(ROW()-2,26)+1, "D20","D21","D28","D29","D81","E21","E31","E51","E61","E62","E73","E83","F01","F11","F12","G12","H41","E01","I21","I41","E91","E92","E23","E81","D22","D20") | D13: =CHOOSE(MOD(ROW()-2,25)+1, "BNF","BND","BNN","BNS","BIA", "BUK","BIR","BBE","BNL","BNL", "BFR","BIG","BSW","BIT","BIT", "BES","BPT","BIE","BPL1","BCZ1", "BAT","BAT","BUK","BIG","BND") | E13: ="01" | F13: =CHOOSE(MOD(ROW()-2,25)+1, "D20","D21","D28","D29","D81", "E21","E31","E51","E61","E62", "E73","E83","F01","F11","F12", "G12","H41","E01","E92","E92", "E92","E92","E21","E83","D22") | G13: {=INDEX('BIE Creation Sheet'!X:X,INT((ROW()-2)/25)+2)} | H13: {=INDEX('BIE Creation Sheet'!R:R,INT((ROW()-2)/25)+2)} | I13: =CHOOSE(MOD(ROW()-2,25)+1, "FI","DK","SV","NO","DE", "GB","IR","BE","NL","NL", "FR","DE","CH","IT","IT", "ES","PT","GB","PL","CZ", "AT","AT","GB","DE","DK") | J13: =0.01 | L13: E73 | M13: BFR | N13: FR | O13: E73
B14: {=INDEX('BIE Creation Sheet'!L:L,INT((ROW()-2)/25)+2)} | C14: =CHOOSE(MOD(ROW()-2,26)+1, "D20","D21","D28","D29","D81","E21","E31","E51","E61","E62","E73","E83","F01","F11","F12","G12","H41","E01","I21","I41","E91","E92","E23","E81","D22","D20") | D14: =CHOOSE(MOD(ROW()-2,25)+1, "BNF","BND","BNN","BNS","BIA", "BUK","BIR","BBE","BNL","BNL", "BFR","BIG","BSW","BIT","BIT", "BES","BPT","BIE","BPL1","BCZ1", "BAT","BAT","BUK","BIG","BND") | E14: ="01" | F14: =CHOOSE(MOD(ROW()-2,25)+1, "D20","D21","D28","D29","D81", "E21","E31","E51","E61","E62", "E73","E83","F01","F11","F12", "G12","H41","E01","E92","E92", "E92","E92","E21","E83","D22") | G14: {=INDEX('BIE Creation Sheet'!X:X,INT((ROW()-2)/25)+2)} | H14: {=INDEX('BIE Creation Sheet'!R:R,INT((ROW()-2)/25)+2)} | I14: =CHOOSE(MOD(ROW()-2,25)+1, "FI","DK","SV","NO","DE", "GB","IR","BE","NL","NL", "FR","DE","CH","IT","IT", "ES","PT","GB","PL","CZ", "AT","AT","GB","DE","DK") | J14: =0.01 | L14: E83 | M14: BIG | N14: DE | O14: E83
B15: {=INDEX('BIE Creation Sheet'!L:L,INT((ROW()-2)/25)+2)} | C15: =CHOOSE(MOD(ROW()-2,26)+1, "D20","D21","D28","D29","D81","E21","E31","E51","E61","E62","E73","E83","F01","F11","F12","G12","H41","E01","I21","I41","E91","E92","E23","E81","D22","D20") | D15: =CHOOSE(MOD(ROW()-2,25)+1, "BNF","BND","BNN","BNS","BIA", "BUK","BIR","BBE","BNL","BNL", "BFR","BIG","BSW","BIT","BIT", "BES","BPT","BIE","BPL1","BCZ1", "BAT","BAT","BUK","BIG","BND") | E15: ="01" | F15: =CHOOSE(MOD(ROW()-2,25)+1, "D20","D21","D28","D29","D81", "E21","E31","E51","E61","E62", "E73","E83","F01","F11","F12", "G12","H41","E01","E92","E92", "E92","E92","E21","E83","D22") | G15: {=INDEX('BIE Creation Sheet'!X:X,INT((ROW()-2)/25)+2)} | H15: {=INDEX('BIE Creation Sheet'!R:R,INT((ROW()-2)/25)+2)} | I15: =CHOOSE(MOD(ROW()-2,25)+1, "FI","DK","SV","NO","DE", "GB","IR","BE","NL","NL", "FR","DE","CH","IT","IT", "ES","PT","GB","PL","CZ", "AT","AT","GB","DE","DK") | J15: =0.01 | L15: F01 | M15: BSW | N15: CH | O15: F01
... B27: {=INDEX('BIE Creation Sheet'!L:L,INT((ROW()-2)/25)+2)} | C27: =CHOOSE(MOD(ROW()-2,26)+1, "D20","D21","D28","D29","D81","E21","E31","E51","E61","E62","E73","E83","F01","F11","F12","G12","H41","E01","I21","I41","E91","E92","E23","E81","D22","D20") | D27: =CHOOSE(MOD(ROW()-2,25)+1, "BNF","BND","BNN","BNS","BIA", "BUK","BIR","BBE","BNL","BNL", "BFR","BIG","BSW","BIT","BIT", "BES","BPT","BIE","BPL1","BCZ1", "BAT","BAT","BUK","BIG","BND") | E27: ="01" | F27: =CHOOSE(MOD(ROW()-2,25)+1, "D20","D21","D28","D29","D81", "E21","E31","E51","E61","E62", "E73","E83","F01","F11","F12", "G12","H41","E01","E92","E92", "E92","E92","E21","E83","D22") | G27: {=INDEX('BIE Creation Sheet'!X:X,INT((ROW()-2)/25)+2)} | H27: {=INDEX('BIE Creation Sheet'!R:R,INT((ROW()-2)/25)+2)} | I27: =CHOOSE(MOD(ROW()-2,25)+1, "FI","DK","SV","NO","DE", "GB","IR","BE","NL","NL", "FR","DE","CH","IT","IT", "ES","PT","GB","PL","CZ", "AT","AT","GB","DE","DK") | J27: =0.01 | L27: D22 | M27: BND | N27: DK | O27: D22
B28: {=INDEX('BIE Creation Sheet'!L:L,INT((ROW()-2)/25)+2)} | C28: =CHOOSE(MOD(ROW()-2,26)+1, "D20","D21","D28","D29","D81","E21","E31","E51","E61","E62","E73","E83","F01","F11","F12","G12","H41","E01","I21","I41","E91","E92","E23","E81","D22","D20") | D28: =CHOOSE(MOD(ROW()-2,25)+1, "BNF","BND","BNN","BNS","BIA", "BUK","BIR","BBE","BNL","BNL", "BFR","BIG","BSW","BIT","BIT", "BES","BPT","BIE","BPL1","BCZ1", "BAT","BAT","BUK","BIG","BND") | E28: ="01" | F28: =CHOOSE(MOD(ROW()-2,25)+1, "D20","D21","D28","D29","D81", "E21","E31","E51","E61","E62", "E73","E83","F01","F11","F12", "G12","H41","E01","E92","E92", "E92","E92","E21","E83","D22") | G28: {=INDEX('BIE Creation Sheet'!X:X,INT((ROW()-2)/25)+2)} | H28: {=INDEX('BIE Creation Sheet'!R:R,INT((ROW()-2)/25)+2)} | I28: =CHOOSE(MOD(ROW()-2,25)+1, "FI","DK","SV","NO","DE", "GB","IR","BE","NL","NL", "FR","DE","CH","IT","IT", "ES","PT","GB","PL","CZ", "AT","AT","GB","DE","DK") | J28: =0.01
B29: {=INDEX('BIE Creation Sheet'!L:L,INT((ROW()-2)/25)+2)} | C29: =CHOOSE(MOD(ROW()-2,26)+1, "D20","D21","D28","D29","D81","E21","E31","E51","E61","E62","E73","E83","F01","F11","F12","G12","H41","E01","I21","I41","E91","E92","E23","E81","D22","D20") | D29: =CHOOSE(MOD(ROW()-2,25)+1, "BNF","BND","BNN","BNS","BIA", "BUK","BIR","BBE","BNL","BNL", "BFR","BIG","BSW","BIT","BIT", "BES","BPT","BIE","BPL1","BCZ1", "BAT","BAT","BUK","BIG","BND") | E29: ="01" | F29: =CHOOSE(MOD(ROW()-2,25)+1, "D20","D21","D28","D29","D81", "E21","E31","E51","E61","E62", "E73","E83","F01","F11","F12", "G12","H41","E01","E92","E92", "E92","E92","E21","E83","D22") | G29: {=INDEX('BIE Creation Sheet'!X:X,INT((ROW()-2)/25)+2)} | H29: {=INDEX('BIE Creation Sheet'!R:R,INT((ROW()-2)/25)+2)} | I29: =CHOOSE(MOD(ROW()-2,25)+1, "FI","DK","SV","NO","DE", "GB","IR","BE","NL","NL", "FR","DE","CH","IT","IT", "ES","PT","GB","PL","CZ", "AT","AT","GB","DE","DK") | J29: =0.01
B30: {=INDEX('BIE Creation Sheet'!L:L,INT((ROW()-2)/25)+2)} | C30: =CHOOSE(MOD(ROW()-2,26)+1, "D20","D21","D28","D29","D81","E21","E31","E51","E61","E62","E73","E83","F01","F11","F12","G12","H41","E01","I21","I41","E91","E92","E23","E81","D22","D20") | D30: =CHOOSE(MOD(ROW()-2,25)+1, "BNF","BND","BNN","BNS","BIA", "BUK","BIR","BBE","BNL","BNL", "BFR","BIG","BSW","BIT","BIT", "BES","BPT","BIE","BPL1","BCZ1", "BAT","BAT","BUK","BIG","BND") | E30: ="01" | F30: =CHOOSE(MOD(ROW()-2,25)+1, "D20","D21","D28","D29","D81", "E21","E31","E51","E61","E62", "E73","E83","F01","F11","F12", "G12","H41","E01","E92","E92", "E92","E92","E21","E83","D22") | G30: {=INDEX('BIE Creation Sheet'!X:X,INT((ROW()-2)/25)+2)} | H30: {=INDEX('BIE Creation Sheet'!R:R,INT((ROW()-2)/25)+2)} | I30: =CHOOSE(MOD(ROW()-2,25)+1, "FI","DK","SV","NO","DE", "GB","IR","BE","NL","NL", "FR","DE","CH","IT","IT", "ES","PT","GB","PL","CZ", "AT","AT","GB","DE","DK") | J30: =0.01
B31: {=INDEX('BIE Creation Sheet'!L:L,INT((ROW()-2)/25)+2)} | C31: =CHOOSE(MOD(ROW()-2,26)+1, "D20","D21","D28","D29","D81","E21","E31","E51","E61","E62","E73","E83","F01","F11","F12","G12","H41","E01","I21","I41","E91","E92","E23","E81","D22","D20") | D31: =CHOOSE(MOD(ROW()-2,25)+1, "BNF","BND","BNN","BNS","BIA", "BUK","BIR","BBE","BNL","BNL", "BFR","BIG","BSW","BIT","BIT", "BES","BPT","BIE","BPL1","BCZ1", "BAT","BAT","BUK","BIG","BND") | E31: ="01" | F31: =CHOOSE(MOD(ROW()-2,25)+1, "D20","D21","D28","D29","D81", "E21","E31","E51","E61","E62", "E73","E83","F01","F11","F12", "G12","H41","E01","E92","E92", "E92","E92","E21","E83","D22") | G31: {=INDEX('BIE Creation Sheet'!X:X,INT((ROW()-2)/25)+2)} | H31: {=INDEX('BIE Creation Sheet'!R:R,INT((ROW()-2)/25)+2)} | I31: =CHOOSE(MOD(ROW()-2,25)+1, "FI","DK","SV","NO","DE", "GB","IR","BE","NL","NL", "FR","DE","CH","IT","IT", "ES","PT","GB","PL","CZ", "AT","AT","GB","DE","DK") | J31: =0.01
B32: {=INDEX('BIE Creation Sheet'!L:L,INT((ROW()-2)/25)+2)} | C32: =CHOOSE(MOD(ROW()-2,26)+1, "D20","D21","D28","D29","D81","E21","E31","E51","E61","E62","E73","E83","F01","F11","F12","G12","H41","E01","I21","I41","E91","E92","E23","E81","D22","D20") | D32: =CHOOSE(MOD(ROW()-2,25)+1, "BNF","BND","BNN","BNS","BIA", "BUK","BIR","BBE","BNL","BNL", "BFR","BIG","BSW","BIT","BIT", "BES","BPT","BIE","BPL1","BCZ1", "BAT","BAT","BUK","BIG","BND") | E32: ="01" | F32: =CHOOSE(MOD(ROW()-2,25)+1, "D20","D21","D28","D29","D81", "E21","E31","E51","E61","E62", "E73","E83","F01","F11","F12", "G12","H41","E01","E92","E92", "E92","E92","E21","E83","D22") | G32: {=INDEX('BIE Creation Sheet'!X:X,INT((ROW()-2)/25)+2)} | H32: {=INDEX('BIE Creation Sheet'!R:R,INT((ROW()-2)/25)+2)} | I32: =CHOOSE(MOD(ROW()-2,25)+1, "FI","DK","SV","NO","DE", "GB","IR","BE","NL","NL", "FR","DE","CH","IT","IT", "ES","PT","GB","PL","CZ", "AT","AT","GB","DE","DK") | J32: =0.01
B33: {=INDEX('BIE Creation Sheet'!L:L,INT((ROW()-2)/25)+2)} | C33: =CHOOSE(MOD(ROW()-2,26)+1, "D20","D21","D28","D29","D81","E21","E31","E51","E61","E62","E73","E83","F01","F11","F12","G12","H41","E01","I21","I41","E91","E92","E23","E81","D22","D20") | D33: =CHOOSE(MOD(ROW()-2,25)+1, "BNF","BND","BNN","BNS","BIA", "BUK","BIR","BBE","BNL","BNL", "BFR","BIG","BSW","BIT","BIT", "BES","BPT","BIE","BPL1","BCZ1", "BAT","BAT","BUK","BIG","BND") | E33: ="01" | F33: =CHOOSE(MOD(ROW()-2,25)+1, "D20","D21","D28","D29","D81", "E21","E31","E51","E61","E62", "E73","E83","F01","F11","F12", "G12","H41","E01","E92","E92", "E92","E92","E21","E83","D22") | G33: {=INDEX('BIE Creation Sheet'!X:X,INT((ROW()-2)/25)+2)} | H33: {=INDEX('BIE Creation Sheet'!R:R,INT((ROW()-2)/25)+2)} | I33: =CHOOSE(MOD(ROW()-2,25)+1, "FI","DK","SV","NO","DE", "GB","IR","BE","NL","NL", "FR","DE","CH","IT","IT", "ES","PT","GB","PL","CZ", "AT","AT","GB","DE","DK") | J33: =0.01
B34: {=INDEX('BIE Creation Sheet'!L:L,INT((ROW()-2)/25)+2)} | C34: =CHOOSE(MOD(ROW()-2,26)+1, "D20","D21","D28","D29","D81","E21","E31","E51","E61","E62","E73","E83","F01","F11","F12","G12","H41","E01","I21","I41","E91","E92","E23","E81","D22","D20") | D34: =CHOOSE(MOD(ROW()-2,25)+1, "BNF","BND","BNN","BNS","BIA", "BUK","BIR","BBE","BNL","BNL", "BFR","BIG","BSW","BIT","BIT", "BES","BPT","BIE","BPL1","BCZ1", "BAT","BAT","BUK","BIG","BND") | E34: ="01" | F34: =CHOOSE(MOD(ROW()-2,25)+1, "D20","D21","D28","D29","D81", "E21","E31","E51","E61","E62", "E73","E83","F01","F11","F12", "G12","H41","E01","E92","E92", "E92","E92","E21","E83","D22") | G34: {=INDEX('BIE Creation Sheet'!X:X,INT((ROW()-2)/25)+2)} | H34: {=INDEX('BIE Creation Sheet'!R:R,INT((ROW()-2)/25)+2)} | I34: =CHOOSE(MOD(ROW()-2,25)+1, "FI","DK","SV","NO","DE", "GB","IR","BE","NL","NL", "FR","DE","CH","IT","IT", "ES","PT","GB","PL","CZ", "AT","AT","GB","DE","DK") | J34: =0.01
B35: {=INDEX('BIE Creation Sheet'!L:L,INT((ROW()-2)/25)+2)} | C35: =CHOOSE(MOD(ROW()-2,26)+1, "D20","D21","D28","D29","D81","E21","E31","E51","E61","E62","E73","E83","F01","F11","F12","G12","H41","E01","I21","I41","E91","E92","E23","E81","D22","D20") | D35: =CHOOSE(MOD(ROW()-2,25)+1, "BNF","BND","BNN","BNS","BIA", "BUK","BIR","BBE","BNL","BNL", "BFR","BIG","BSW","BIT","BIT", "BES","BPT","BIE","BPL1","BCZ1", "BAT","BAT","BUK","BIG","BND") | E35: ="01" | F35: =CHOOSE(MOD(ROW()-2,25)+1, "D20","D21","D28","D29","D81", "E21","E31","E51","E61","E62", "E73","E83","F01","F11","F12", "G12","H41","E01","E92","E92", "E92","E92","E21","E83","D22") | G35: {=INDEX('BIE Creation Sheet'!X:X,INT((ROW()-2)/25)+2)} | H35: {=INDEX('BIE Creation Sheet'!R:R,INT((ROW()-2)/25)+2)} | I35: =CHOOSE(MOD(ROW()-2,25)+1, "FI","DK","SV","NO","DE", "GB","IR","BE","NL","NL", "FR","DE","CH","IT","IT", "ES","PT","GB","PL","CZ", "AT","AT","GB","DE","DK") | J35: =0.01
B36: {=INDEX('BIE Creation Sheet'!L:L,INT((ROW()-2)/25)+2)} | C36: =CHOOSE(MOD(ROW()-2,26)+1, "D20","D21","D28","D29","D81","E21","E31","E51","E61","E62","E73","E83","F01","F11","F12","G12","H41","E01","I21","I41","E91","E92","E23","E81","D22","D20") | D36: =CHOOSE(MOD(ROW()-2,25)+1, "BNF","BND","BNN","BNS","BIA", "BUK","BIR","BBE","BNL","BNL", "BFR","BIG","BSW","BIT","BIT", "BES","BPT","BIE","BPL1","BCZ1", "BAT","BAT","BUK","BIG","BND") | E36: ="01" | F36: =CHOOSE(MOD(ROW()-2,25)+1, "D20","D21","D28","D29","D81", "E21","E31","E51","E61","E62", "E73","E83","F01","F11","F12", "G12","H41","E01","E92","E92", "E92","E92","E21","E83","D22") | G36: {=INDEX('BIE Creation Sheet'!X:X,INT((ROW()-2)/25)+2)} | H36: {=INDEX('BIE Creation Sheet'!R:R,INT((ROW()-2)/25)+2)} | I36: =CHOOSE(MOD(ROW()-2,25)+1, "FI","DK","SV","NO","DE", "GB","IR","BE","NL","NL", "FR","DE","CH","IT","IT", "ES","PT","GB","PL","CZ", "AT","AT","GB","DE","DK") | J36: =0.01
B37: {=INDEX('BIE Creation Sheet'!L:L,INT((ROW()-2)/25)+2)} | C37: =CHOOSE(MOD(ROW()-2,26)+1, "D20","D21","D28","D29","D81","E21","E31","E51","E61","E62","E73","E83","F01","F11","F12","G12","H41","E01","I21","I41","E91","E92","E23","E81","D22","D20") | D37: =CHOOSE(MOD(ROW()-2,25)+1, "BNF","BND","BNN","BNS","BIA", "BUK","BIR","BBE","BNL","BNL", "BFR","BIG","BSW","BIT","BIT", "BES","BPT","BIE","BPL1","BCZ1", "BAT","BAT","BUK","BIG","BND") | E37: ="01" | F37: =CHOOSE(MOD(ROW()-2,25)+1, "D20","D21","D28","D29","D81", "E21","E31","E51","E61","E62", "E73","E83","F01","F11","F12", "G12","H41","E01","E92","E92", "E92","E92","E21","E83","D22") | G37: {=INDEX('BIE Creation Sheet'!X:X,INT((ROW()-2)/25)+2)} | H37: {=INDEX('BIE Creation Sheet'!R:R,INT((ROW()-2)/25)+2)} | I37: =CHOOSE(MOD(ROW()-2,25)+1, "FI","DK","SV","NO","DE", "GB","IR","BE","NL","NL", "FR","DE","CH","IT","IT", "ES","PT","GB","PL","CZ", "AT","AT","GB","DE","DK") | J37: =0.01
B38: {=INDEX('BIE Creation Sheet'!L:L,INT((ROW()-2)/25)+2)} | C38: =CHOOSE(MOD(ROW()-2,26)+1, "D20","D21","D28","D29","D81","E21","E31","E51","E61","E62","E73","E83","F01","F11","F12","G12","H41","E01","I21","I41","E91","E92","E23","E81","D22","D20") | D38: =CHOOSE(MOD(ROW()-2,25)+1, "BNF","BND","BNN","BNS","BIA", "BUK","BIR","BBE","BNL","BNL", "BFR","BIG","BSW","BIT","BIT", "BES","BPT","BIE","BPL1","BCZ1", "BAT","BAT","BUK","BIG","BND") | E38: ="01" | F38: =CHOOSE(MOD(ROW()-2,25)+1, "D20","D21","D28","D29","D81", "E21","E31","E51","E61","E62", "E73","E83","F01","F11","F12", "G12","H41","E01","E92","E92", "E92","E92","E21","E83","D22") | G38: {=INDEX('BIE Creation Sheet'!X:X,INT((ROW()-2)/25)+2)} | H38: {=INDEX('BIE Creation Sheet'!R:R,INT((ROW()-2)/25)+2)} | I38: =CHOOSE(MOD(ROW()-2,25)+1, "FI","DK","SV","NO","DE", "GB","IR","BE","NL","NL", "FR","DE","CH","IT","IT", "ES","PT","GB","PL","CZ", "AT","AT","GB","DE","DK") | J38: =0.01
B39: {=INDEX('BIE Creation Sheet'!L:L,INT((ROW()-2)/25)+2)} | C39: =CHOOSE(MOD(ROW()-2,26)+1, "D20","D21","D28","D29","D81","E21","E31","E51","E61","E62","E73","E83","F01","F11","F12","G12","H41","E01","I21","I41","E91","E92","E23","E81","D22","D20") | D39: =CHOOSE(MOD(ROW()-2,25)+1, "BNF","BND","BNN","BNS","BIA", "BUK","BIR","BBE","BNL","BNL", "BFR","BIG","BSW","BIT","BIT", "BES","BPT","BIE","BPL1","BCZ1", "BAT","BAT","BUK","BIG","BND") | E39: ="01" | F39: =CHOOSE(MOD(ROW()-2,25)+1, "D20","D21","D28","D29","D81", "E21","E31","E51","E61","E62", "E73","E83","F01","F11","F12", "G12","H41","E01","E92","E92", "E92","E92","E21","E83","D22") | G39: {=INDEX('BIE Creation Sheet'!X:X,INT((ROW()-2)/25)+2)} | H39: {=INDEX('BIE Creation Sheet'!R:R,INT((ROW()-2)/25)+2)} | I39: =CHOOSE(MOD(ROW()-2,25)+1, "FI","DK","SV","NO","DE", "GB","IR","BE","NL","NL", "FR","DE","CH","IT","IT", "ES","PT","GB","PL","CZ", "AT","AT","GB","DE","DK") | J39: =0.01
... B178: {=INDEX('BIE Creation Sheet'!L:L,INT((ROW()-2)/25)+2)} | C178: =CHOOSE(MOD(ROW()-2,26)+1, "D20","D21","D28","D29","D81","E21","E31","E51","E61","E62","E73","E83","F01","F11","F12","G12","H41","E01","I21","I41","E91","E92","E23","E81","D22","D20") | D178: =CHOOSE(MOD(ROW()-2,25)+1, "BNF","BND","BNN","BNS","BIA", "BUK","BIR","BBE","BNL","BNL", "BFR","BIG","BSW","BIT","BIT", "BES","BPT","BIE","BPL1","BCZ1", "BAT","BAT","BUK","BIG","BND") | E178: ="01" | F178: =CHOOSE(MOD(ROW()-2,25)+1, "D20","D21","D28","D29","D81", "E21","E31","E51","E61","E62", "E73","E83","F01","F11","F12", "G12","H41","E01","E92","E92", "E92","E92","E21","E83","D22") | G178: {=INDEX('BIE Creation Sheet'!X:X,INT((ROW()-2)/25)+2)} | H178: {=INDEX('BIE Creation Sheet'!R:R,INT((ROW()-2)/25)+2)} | I178: =CHOOSE(MOD(ROW()-2,25)+1, "FI","DK","SV","NO","DE", "GB","IR","BE","NL","NL", "FR","DE","CH","IT","IT", "ES","PT","GB","PL","CZ", "AT","AT","GB","DE","DK") | J178: =0.01

Sheet Sheet3
A1: Log Automate Studio 24.1 SAP System: Client: SAP User - Q01:400:MMASTER Script Name - ZMPS3_S4H.Txr Mode - Standard (Non Batch without controls) Start Row - 2 End Row - 0 Number of Errors - 543 Records Uploaded - 57 Date and Time - 10/07/2026 15:04:10 Execution Time - 0:01:11 Run Reason - | B1: Material Number RMMG1-MATNR | C1: Sales Organization RMMG1-VKORG | D1: Distribution Channel RMMG1-VTWEG | E1: Delivering Plant (Own or External) MVKE-DWERK | F1: Material Pricing Group MVKE-KONDM | G1: Product hierarchy MVKE-PRODH | M1: No of materials | N1: Entries per material | O1: Drag it to row
B2: {=INDEX(Sheet2!B:B,ROW())} | C2: {=INDEX(Sheet2!D:D,ROW())} | D2: ="13" | E2: {=INDEX(Sheet2!F:F,ROW())} | F2: {=INDEX('BIE Creation Sheet'!X:X,INT((ROW()-2)/25)+2)} | G2: {=INDEX('BIE Creation Sheet'!R:R,INT((ROW()-2)/25)+2)} | H2: Add language Descriptions manually after creation
B3: {=INDEX(Sheet2!B:B,ROW())} | C3: {=INDEX(Sheet2!D:D,ROW())} | D3: ="13" | E3: {=INDEX(Sheet2!F:F,ROW())} | F3: {=INDEX('BIE Creation Sheet'!X:X,INT((ROW()-2)/25)+2)} | G3: {=INDEX('BIE Creation Sheet'!R:R,INT((ROW()-2)/25)+2)} | M3: 2 | N3: 25 | O3: =M3*N3+1
B4: {=INDEX(Sheet2!B:B,ROW())} | C4: {=INDEX(Sheet2!D:D,ROW())} | D4: ="13" | E4: {=INDEX(Sheet2!F:F,ROW())} | F4: {=INDEX('BIE Creation Sheet'!X:X,INT((ROW()-2)/25)+2)} | G4: {=INDEX('BIE Creation Sheet'!R:R,INT((ROW()-2)/25)+2)}
B5: {=INDEX(Sheet2!B:B,ROW())} | C5: {=INDEX(Sheet2!D:D,ROW())} | D5: ="13" | E5: {=INDEX(Sheet2!F:F,ROW())} | F5: {=INDEX('BIE Creation Sheet'!X:X,INT((ROW()-2)/25)+2)} | G5: {=INDEX('BIE Creation Sheet'!R:R,INT((ROW()-2)/25)+2)}
B6: {=INDEX(Sheet2!B:B,ROW())} | C6: {=INDEX(Sheet2!D:D,ROW())} | D6: ="13" | E6: {=INDEX(Sheet2!F:F,ROW())} | F6: {=INDEX('BIE Creation Sheet'!X:X,INT((ROW()-2)/25)+2)} | G6: {=INDEX('BIE Creation Sheet'!R:R,INT((ROW()-2)/25)+2)}
B7: {=INDEX(Sheet2!B:B,ROW())} | C7: {=INDEX(Sheet2!D:D,ROW())} | D7: ="13" | E7: {=INDEX(Sheet2!F:F,ROW())} | F7: {=INDEX('BIE Creation Sheet'!X:X,INT((ROW()-2)/25)+2)} | G7: {=INDEX('BIE Creation Sheet'!R:R,INT((ROW()-2)/25)+2)}
B8: {=INDEX(Sheet2!B:B,ROW())} | C8: {=INDEX(Sheet2!D:D,ROW())} | D8: ="13" | E8: {=INDEX(Sheet2!F:F,ROW())} | F8: {=INDEX('BIE Creation Sheet'!X:X,INT((ROW()-2)/25)+2)} | G8: {=INDEX('BIE Creation Sheet'!R:R,INT((ROW()-2)/25)+2)}
B9: {=INDEX(Sheet2!B:B,ROW())} | C9: {=INDEX(Sheet2!D:D,ROW())} | D9: ="13" | E9: {=INDEX(Sheet2!F:F,ROW())} | F9: {=INDEX('BIE Creation Sheet'!X:X,INT((ROW()-2)/25)+2)} | G9: {=INDEX('BIE Creation Sheet'!R:R,INT((ROW()-2)/25)+2)}
B10: {=INDEX(Sheet2!B:B,ROW())} | C10: {=INDEX(Sheet2!D:D,ROW())} | D10: ="13" | E10: {=INDEX(Sheet2!F:F,ROW())} | F10: {=INDEX('BIE Creation Sheet'!X:X,INT((ROW()-2)/25)+2)} | G10: {=INDEX('BIE Creation Sheet'!R:R,INT((ROW()-2)/25)+2)}
B11: {=INDEX(Sheet2!B:B,ROW())} | C11: {=INDEX(Sheet2!D:D,ROW())} | D11: ="13" | E11: {=INDEX(Sheet2!F:F,ROW())} | F11: {=INDEX('BIE Creation Sheet'!X:X,INT((ROW()-2)/25)+2)} | G11: {=INDEX('BIE Creation Sheet'!R:R,INT((ROW()-2)/25)+2)}
B12: {=INDEX(Sheet2!B:B,ROW())} | C12: {=INDEX(Sheet2!D:D,ROW())} | D12: ="13" | E12: {=INDEX(Sheet2!F:F,ROW())} | F12: {=INDEX('BIE Creation Sheet'!X:X,INT((ROW()-2)/25)+2)} | G12: {=INDEX('BIE Creation Sheet'!R:R,INT((ROW()-2)/25)+2)}
B13: {=INDEX(Sheet2!B:B,ROW())} | C13: {=INDEX(Sheet2!D:D,ROW())} | D13: ="13" | E13: {=INDEX(Sheet2!F:F,ROW())} | F13: {=INDEX('BIE Creation Sheet'!X:X,INT((ROW()-2)/25)+2)} | G13: {=INDEX('BIE Creation Sheet'!R:R,INT((ROW()-2)/25)+2)}
B14: {=INDEX(Sheet2!B:B,ROW())} | C14: {=INDEX(Sheet2!D:D,ROW())} | D14: ="13" | E14: {=INDEX(Sheet2!F:F,ROW())} | F14: {=INDEX('BIE Creation Sheet'!X:X,INT((ROW()-2)/25)+2)} | G14: {=INDEX('BIE Creation Sheet'!R:R,INT((ROW()-2)/25)+2)}
B15: {=INDEX(Sheet2!B:B,ROW())} | C15: {=INDEX(Sheet2!D:D,ROW())} | D15: ="13" | E15: {=INDEX(Sheet2!F:F,ROW())} | F15: {=INDEX('BIE Creation Sheet'!X:X,INT((ROW()-2)/25)+2)} | G15: {=INDEX('BIE Creation Sheet'!R:R,INT((ROW()-2)/25)+2)}
... B52: {=INDEX(Sheet2!B:B,ROW())} | C52: {=INDEX(Sheet2!D:D,ROW())} | D52: ="13" | E52: {=INDEX(Sheet2!F:F,ROW())} | F52: {=INDEX('BIE Creation Sheet'!X:X,INT((ROW()-2)/25)+2)} | G52: {=INDEX('BIE Creation Sheet'!R:R,INT((ROW()-2)/25)+2)}
B53: {=INDEX(Sheet2!B:B,ROW())}
B54: {=INDEX(Sheet2!B:B,ROW())}
B55: {=INDEX(Sheet2!B:B,ROW())}
B56: {=INDEX(Sheet2!B:B,ROW())}
B57: {=INDEX(Sheet2!B:B,ROW())}
B58: {=INDEX(Sheet2!B:B,ROW())}
B59: {=INDEX(Sheet2!B:B,ROW())}
B60: {=INDEX(Sheet2!B:B,ROW())}
B61: {=INDEX(Sheet2!B:B,ROW())}
B62: {=INDEX(Sheet2!B:B,ROW())}
B63: {=INDEX(Sheet2!B:B,ROW())}
B64: {=INDEX(Sheet2!B:B,ROW())}
... B233: {=INDEX(Sheet2!B:B,ROW())}

Sheet BIE Creation Sheet
A1: REQUESTOR'S NAME | B1: Segment Data | C1: BASE UNIT OF MEASURE | D1: MATERIAL TYPE | E1: ITEM CATEGORY GROUP (General and Item) | F1: MANUFACTURER | G1: COUNTRY OF ORIGIN | H1: REGION OF ORIGIN | I1: Plant with purchasing, foreign trade, MRP1 and accounting views only | J1: Sales Organisations | K1: Create / Change Local Office Plant Views | L1: MATERIAL NUMBER TO BE CREATED- maximum length is 18 | M1: MATERIAL DESCRIPTION - UPPER CASE and MAXIMUM 40 CHARACTERS | N1: PURCHASING GROUP | O1: MRP TYPE | P1: DIVISION | Q1: MATERIAL GROUP | R1: PRODUCT HIERARCHY | S1: GROSS WEIGHT-TO 3 DECIMAL PLACES | T1: NET WEIGHT-TO 3 DECIMAL PLACES | U1: VOLUME-TO 3 DECIMAL PLACES | V1: SIZE/DIMENSIONS-for single packed unit | W1: INDUSTRY STD DESCRIPTION | X1: MATERIAL PRICING GROUP | Y1: VOLUME REBATE GROUP | Z1: DELIVERING PLANT | AA1: SERIAL NUMBERS | AB1: MINIMUM ORDER QUANTITY | AC1: MINIMUM DELIVERY QUANTITY | AD1: DELIVERY UNIT | AE1: COMMODITY CODE | AF1: BUK STANDARD COST PRICE IN £-TO 2 DECIMAL PLACES | AG1: LOCAL OFFICE STANDARD COST PRICE IN Euro -TO 2 DECIMAL PLACES | AH1: LOCAL OFFICE STANDARD COST PRICE IN other currency -TO 2 DECIMAL PLACES | AI1: Other currency | AJ1: For internal use only | AK1: For internal use only | AL1: For internal use only | AM1: For internal use only
A2: Ian Thomasson | B2: SD 1 | C2: COP | D2: ZBR3 | E2: LEIS | F2: ZZE0 | I2: E01,D2*,D81,E2*,E31,E51,E6*,E73,E81,E9*,F01,F1*,G1*,H41,I21,I31,I41 | K2: CREATE | L2: MAT 1 | M2: DES 1 | P2: 50 | Q2: MG 1 | R2: PH 1 | W2: =L2 | X2: MGP 1 | Y2: 1 | AB2: 1 | AC2: 1 | AD2: 1 | AJ2: 11 | AL2: 2 | AM2: ZBR3 | AN2: LEIS
A3: Ian Thomasson | B3: SD 2 | C3: COP | D3: ZBR3 | E3: LEIS | F3: ZZE0 | I3: E01,D2*,D81,E2*,E31,E51,E6*,E73,E81,E9*,F01,F1*,G1*,H41,I21,I31,I41 | K3: CREATE | L3: MAT 2 | M3: DES 2 | P3: 50 | Q3: MG 2 | R3: PH 2 | W3: =L3 | X3: MGP 2 | Y3: 2 | AB3: 1 | AC3: 1 | AD3: 1 | AJ3: 11 | AK3: U | AL3: 40 | AM3: ZBR3 | AN3: LEIS
A4: Ian Thomasson | B4: SD 3 | C4: COP | D4: ZBR3 | E4: LEIS | F4: ZZE0 | I4: E01,D2*,D81,E2*,E31,E51,E6*,E73,E81,E9*,F01,F1*,G1*,H41,I21,I31,I41 | K4: CREATE | L4: MAT 3 | M4: DES 3 | P4: 50 | Q4: MG 3 | R4: PH 3 | W4: =L4 | X4: MGP 3 | Y4: 3 | AB4: 1 | AC4: 1 | AD4: 1 | AJ4: 11 | AL4: 2 | AM4: ZBR3 | AN4: LEIS
A5: Ian Thomasson | B5: SD 4 | C5: COP | D5: ZBR3 | E5: LEIS | F5: ZZE0 | I5: E01,D2*,D81,E2*,E31,E51,E6*,E73,E81,E9*,F01,F1*,G1*,H41,I21,I31,I41 | K5: CREATE | L5: MAT 4 | M5: DES 4 | P5: 50 | Q5: MG 4 | R5: PH 4 | W5: =L5 | X5: MGP 4 | Y5: 4 | AB5: 1 | AC5: 1 | AD5: 1 | AJ5: 11 | AL5: 2 | AM5: ZBR3 | AN5: LEIS
A6: Ian Thomasson | B6: SD 5 | C6: COP | D6: ZBR3 | E6: LEIS | F6: ZZE0 | I6: E01,D2*,D81,E2*,E31,E51,E6*,E73,E81,E9*,F01,F1*,G1*,H41,I21,I31,I41 | K6: CREATE | L6: MAT 5 | M6: DES 5 | P6: 50 | Q6: MG 5 | R6: PH 5 | W6: =L6 | X6: MGP 5 | Y6: 5 | AB6: 1 | AC6: 1 | AD6: 1 | AJ6: 10 | AL6: 2 | AM6: ZBR3 | AN6: LEIS
A7: Ian Thomasson | B7: SD 6 | C7: COP | D7: ZBR3 | E7: LEIS | F7: ZZE0 | I7: E01,D2*,D81,E2*,E31,E51,E6*,E73,E81,E9*,F01,F1*,G1*,H41,I21,I31,I41 | K7: CREATE | L7: MAT 6 | M7: DES 6 | P7: 50 | Q7: MG 6 | R7: PH 6 | W7: =L7 | X7: MGP 6 | Y7: 6 | AB7: 1 | AC7: 1 | AD7: 1 | AJ7: 10 | AL7: 2 | AM7: ZBR3 | AN7: LEIS
A8: Ian Thomasson | B8: SD 7 | C8: COP | D8: ZBR3 | E8: LEIS | F8: ZZE0 | I8: E01,D2*,D81,E2*,E31,E51,E6*,E73,E81,E9*,F01,F1*,G1*,H41,I21,I31,I41 | K8: CREATE | L8: MAT 7 | M8: DES 7 | P8: 50 | Q8: MG 7 | R8: PH 7 | W8: =L8 | X8: MGP 7 | Y8: 7 | AB8: 1 | AC8: 1 | AD8: 1 | AJ8: 10 | AL8: 2 | AM8: ZBR3 | AN8: LEIS
A9: Ian Thomasson | B9: SD 8 | C9: COP | D9: ZBR3 | E9: LEIS | F9: ZZE0 | I9: E01,D2*,D81,E2*,E31,E51,E6*,E73,E81,E9*,F01,F1*,G1*,H41,I21,I31,I41 | K9: CREATE | L9: MAT 8 | M9: DES 8 | P9: 50 | Q9: MG 8 | R9: PH 8 | W9: =L9 | X9: MGP 8 | Y9: 8 | AB9: 1 | AC9: 1 | AD9: 1 | AJ9: 10 | AL9: 2 | AM9: ZBR3 | AN9: LEIS
A10: Ian Thomasson | B10: SD 9 | C10: COP | D10: ZBR3 | E10: LEIS | F10: ZZE0 | I10: E01,D2*,D81,E2*,E31,E51,E6*,E73,E81,E9*,F01,F1*,G1*,H41,I21,I31,I41 | K10: CREATE | L10: MAT 9 | M10: DES 9 | P10: 50 | Q10: MG 9 | R10: PH 9 | W10: =L10 | X10: MGP 9 | Y10: 9 | AB10: 1 | AC10: 1 | AD10: 1 | AJ10: 10 | AL10: 2 | AM10: ZBR3 | AN10: LEIS
A11: Ian Thomasson | B11: SD 10 | C11: COP | D11: ZBR3 | E11: LEIS | F11: ZZE0 | I11: E01,D2*,D81,E2*,E31,E51,E6*,E73,E81,E9*,F01,F1*,G1*,H41,I21,I31,I41 | K11: CREATE | L11: MAT 10 | M11: DES 10 | P11: 50 | Q11: MG 10 | R11: PH 10 | W11: =L11 | X11: MGP 10 | Y11: 10 | AB11: 1 | AC11: 1 | AD11: 1 | AJ11: 10 | AL11: 2 | AM11: ZBR3 | AN11: LEIS
A12: Ian Thomasson | B12: SD 11 | C12: COP | D12: ZBR3 | E12: LEIS | F12: ZZE0 | I12: E01,D2*,D81,E2*,E31,E51,E6*,E73,E81,E9*,F01,F1*,G1*,H41,I21,I31,I41 | K12: CREATE | L12: MAT 11 | M12: DES 11 | P12: 50 | Q12: MG 11 | R12: PH 11 | W12: =L12 | X12: MGP 11 | Y12: 11 | AB12: 1 | AC12: 1 | AD12: 1 | AJ12: 10 | AL12: 2 | AM12: ZBR3 | AN12: LEIS
A13: Ian Thomasson | B13: SD 12 | C13: COP | D13: ZBR3 | E13: LEIS | F13: ZZE0 | I13: E01,D2*,D81,E2*,E31,E51,E6*,E73,E81,E9*,F01,F1*,G1*,H41,I21,I31,I41 | K13: CREATE | L13: MAT 12 | M13: DES 12 | P13: 50 | Q13: MG 12 | R13: PH 12 | W13: =L13 | X13: MGP 12 | Y13: 12 | AB13: 1 | AC13: 1 | AD13: 1 | AJ13: 10 | AL13: 2 | AM13: ZBR3 | AN13: LEIS
A14: Ian Thomasson | B14: SD 13 | C14: COP | D14: ZBR3 | E14: LEIS | F14: ZZE0 | I14: E01,D2*,D81,E2*,E31,E51,E6*,E73,E81,E9*,F01,F1*,G1*,H41,I21,I31,I41 | K14: CREATE | L14: MAT 13 | M14: DES 13 | P14: 50 | Q14: MG 13 | R14: PH 13 | W14: =L14 | X14: MGP 13 | Y14: 13 | AB14: 1 | AC14: 1 | AD14: 1 | AJ14: 10 | AL14: 2 | AM14: ZBR3 | AN14: LEIS
A15: Ian Thomasson | B15: SD 14 | C15: COP | D15: ZBR3 | E15: LEIS | F15: ZZE0 | I15: E01,D2*,D81,E2*,E31,E51,E6*,E73,E81,E9*,F01,F1*,G1*,H41,I21,I31,I41 | K15: CREATE | L15: MAT 14 | M15: DES 14 | P15: 50 | Q15: MG 14 | R15: PH 14 | W15: =L15 | X15: MGP 14 | Y15: 14 | AB15: 1 | AC15: 1 | AD15: 1 | AJ15: 10 | AL15: 2 | AM15: ZBR3 | AN15: LEIS
... A17: Ian Thomasson | B17: SD 16 | C17: COP | D17: ZBR3 | E17: LEIS | F17: ZZE0 | I17: E01,D2*,D81,E2*,E31,E51,E6*,E73,E81,E9*,F01,F1*,G1*,H41,I21,I31,I41 | K17: CREATE | L17: MAT 16 | M17: DES 16 | P17: 50 | Q17: MG 16 | R17: PH 16 | W17: =L17 | X17: MGP 16 | Y17: 16 | AB17: 1 | AC17: 1 | AD17: 1 | AJ17: 11 | AL17: 2 | AM17: ZBR3 | AN17: LEIS
A18: Ian Thomasson | B18: SD 17 | C18: COP | D18: ZBR3 | E18: LEIS | F18: ZZE0 | I18: E01,D2*,D81,E2*,E31,E51,E6*,E73,E81,E9*,F01,F1*,G1*,H41,I21,I31,I41 | K18: CREATE | L18: MAT 17 | M18: DES 17 | P18: 50 | Q18: MG 17 | R18: PH 17 | W18: =L18 | X18: MGP 17 | Y18: 17 | AB18: 1 | AC18: 1 | AD18: 1 | AJ18: =MID(L18,AL18,1) | AK18: =EXACT(MID(L16,1,5),"ZWMPS") | AL18: =LEN(L16) | AM18: =LEN(M16)
A19: Ian Thomasson | B19: SD 18 | C19: COP | D19: ZBR3 | E19: LEIS | F19: ZZE0 | I19: E01,D2*,D81,E2*,E31,E51,E6*,E73,E81,E9*,F01,F1*,G1*,H41,I21,I31,I41 | K19: CREATE | L19: MAT 18 | M19: DES 18 | P19: 50 | Q19: MG 18 | R19: PH 18 | W19: =L19 | X19: MGP 18 | Y19: 18 | AB19: 1 | AC19: 1 | AD19: 1 | AJ19: =MID(L19,AL19,1) | AK19: =EXACT(MID(L19,1,5),"ZWMPS") | AL19: =LEN(L19) | AM19: =LEN(M19)
A20: Ian Thomasson | B20: SD 19 | C20: COP | D20: ZBR3 | E20: LEIS | F20: ZZE0 | I20: E01,D2*,D81,E2*,E31,E51,E6*,E73,E81,E9*,F01,F1*,G1*,H41,I21,I31,I41 | K20: CREATE | L20: MAT 19 | M20: DES 19 | P20: 50 | Q20: MG 19 | R20: PH 19 | W20: =L20 | X20: MGP 19 | Y20: 19 | AB20: 1 | AC20: 1 | AD20: 1 | AJ20: =MID(L20,AL20,1) | AK20: =EXACT(MID(L20,1,5),"ZWMPS") | AL20: =LEN(L20) | AM20: =LEN(M20)
A21: Ian Thomasson | B21: SD 20 | C21: COP | D21: ZBR3 | E21: LEIS | F21: ZZE0 | I21: E01,D2*,D81,E2*,E31,E51,E6*,E73,E81,E9*,F01,F1*,G1*,H41,I21,I31,I41 | K21: CREATE | L21: MAT 20 | M21: DES 20 | P21: 50 | Q21: MG 20 | R21: PH 20 | W21: =L21 | X21: MGP 20 | Y21: 20 | AB21: 1 | AC21: 1 | AD21: 1 | AJ21: =MID(L21,AL21,1) | AK21: =EXACT(MID(L17,1,5),"ZWMPS") | AL21: =LEN(L17) | AM21: =LEN(M17)
A22: Ian Thomasson | B22: SD 21 | C22: COP | D22: ZBR3 | E22: LEIS | F22: ZZE0 | I22: E01,D2*,D81,E2*,E31,E51,E6*,E73,E81,E9*,F01,F1*,G1*,H41,I21,I31,I41 | K22: CREATE | L22: MAT 21 | M22: DES 21 | P22: 50 | Q22: MG 21 | R22: PH 21 | W22: =L22 | X22: MGP 21 | Y22: 21 | AB22: 1 | AC22: 1 | AD22: 1 | AJ22: =MID(L22,AL22,1) | AK22: =EXACT(MID(L22,1,5),"ZWMPS") | AL22: =LEN(L22) | AM22: =LEN(M22)
A23: Ian Thomasson | B23: SD 22 | C23: COP | D23: ZBR3 | E23: LEIS | F23: ZZE0 | I23: E01,D2*,D81,E2*,E31,E51,E6*,E73,E81,E9*,F01,F1*,G1*,H41,I21,I31,I41 | K23: CREATE | L23: MAT 22 | M23: DES 22 | P23: 50 | Q23: MG 22 | R23: PH 22 | W23: =L23 | X23: MGP 22 | Y23: 22 | AB23: 1 | AC23: 1 | AD23: 1 | AJ23: =MID(L23,AL23,1) | AK23: =EXACT(MID(L23,1,5),"ZWMPS") | AL23: =LEN(L23) | AM23: =LEN(M23)
A24: Ian Thomasson | B24: SD 23 | C24: COP | D24: ZBR3 | E24: LEIS | F24: ZZE0 | I24: E01,D2*,D81,E2*,E31,E51,E6*,E73,E81,E9*,F01,F1*,G1*,H41,I21,I31,I41 | K24: CREATE | L24: MAT 23 | M24: DES 23 | P24: 50 | Q24: MG 23 | R24: PH 23 | W24: =L24 | X24: MGP 23 | Y24: 23 | AB24: 1 | AC24: 1 | AD24: 1 | AJ24: =MID(L24,AL24,1) | AK24: =EXACT(MID(L24,1,5),"ZWMPS") | AL24: =LEN(L24) | AM24: =LEN(M24)
A25: Ian Thomasson | B25: SD 24 | C25: COP | D25: ZBR3 | E25: LEIS | F25: ZZE0 | I25: E01,D2*,D81,E2*,E31,E51,E6*,E73,E81,E9*,F01,F1*,G1*,H41,I21,I31,I41 | K25: CREATE | L25: MAT 24 | M25: DES 24 | P25: 50 | Q25: MG 24 | R25: PH 24 | W25: =L25 | X25: MGP 24 | Y25: 24 | AB25: 1 | AC25: 1 | AD25: 1 | AJ25: =MID(L25,AL25,1) | AK25: =EXACT(MID(L25,1,5),"ZWMPS") | AL25: =LEN(L25) | AM25: =LEN(M25)
L26: MAT 25 | M26: DES 25 | W26: =L26 | X26: MGP 25 | Y26: 25
B27: Add language Descriptions manually after creation | L27: MAT 26 | M27: DES 26 | W27: =L27 | X27: MGP 26 | Y27: 26
L28: MAT 27 | M28: DES 27 | W28: =L28 | X28: MGP 27 | Y28: 27
L29: MAT 28 | M29: DES 28 | W29: =L29 | X29: MGP 28 | Y29: 28
L30: MAT 29 | M30: DES 29 | W30: =L30 | X30: MGP 29 | Y30: 29
L31: MAT 30 | M31: DES 30 | W31: =L31 | X31: MGP 30 | Y31: 30
L32: MAT 31 | M32: DES 31 | W32: =L32 | X32: MGP 31 | Y32: 31
L33: MAT 32 | M33: DES 32 | W33: =L33 | X33: MGP 32 | Y33: 32
L34: MAT 33 | M34: DES 33 | W34: =L34 | X34: MGP 33 | Y34: 33
L35: MAT 34 | M35: DES 34 | W35: =L35 | X35: MGP 34 | Y35: 34
L36: MAT 35 | M36: DES 35 | W36: =L36 | X36: MGP 35 | Y36: 35
L37: MAT 36 | M37: DES 36 | W37: =L37 | X37: MGP 36 | Y37: 36
L38: MAT 37 | M38: DES 37 | W38: =L38 | X38: MGP 37 | Y38: 37
L39: MAT 38 | M39: DES 38 | W39: =L39 | X39: MGP 38 | Y39: 38
L40: MAT 39 | M40: DES 39
L41: MAT 40 | M41: DES 40
...
